Workbook

Sheet Products
A1: ProductID | B1: ProductName | C1: Category | D1: SubCategory | E1: UnitCost | F1: Supplier
A2: P005 | B2: Laptops Deluxe 892 | C2: Electronics | D2: Laptops | E2: 2992.45 | F2: Padma Wholesale
A3: P032 | B3: Pens Mini 821 | C3: Office Supplies | D3: Pens | E3: 3230.29 | F3: Global Sourcing Ltd
A4: P028 | B4: Binders Max 146 | C4: Office Supplies | D4: Binders | E4: 540.61 | F4: Global Sourcing Ltd
A5: P023 | B5: Decor Prime 953 | C5: Furniture | D5: Decor | E5: 293.81 | F5: Padma Wholesale
A6: P030 | B6: Binders Lite 858 | C6: Office Supplies | D6: Binders | E6: 4898.87 | F6: Ganges Supply Co
A7: P060 | B7: Personal Care Mini 941 | C7: Groceries | D7: Personal Care | E7: 4796.46 | F7: Meghna Imports
A8: P042 | B8: Women Eco 309 | C8: Apparel | D8: Women | E8: 1863.64 | F8: Padma Wholesale
A9: P026 | B9: Paper Lite 570 | C9: Office Supplies | D9: Paper | E9: 4175.62 | F9: Meghna Imports
A10: P025 | B10: Paper Eco 932 | C10: Office Supplies | D10: Paper | E10: 553.28 | F10: Ganges Supply Co
A11: P021 | B11: Storage Mini 899 | C11: Furniture | D11: Storage | E11: 1284.47 | F11: Northline Traders
A12: P013 | B12: Chairs Mini 737 | C12: Furniture | D12: Chairs | E12: 914.48 | F12: Meghna Imports
A13: P027 | B13: Paper Prime 195 | C13: Office Supplies | D13: Paper | E13: 4627.97 | F13: Northline Traders
... A56: P059 | B56: Personal Care Mini 570 | C56: Groceries | D56: Personal Care | E56: 730.17 | F56: Padma Wholesale

Sheet Customers
A1: CustomerID | B1: CustomerName | C1: FirstName | D1: LastName | E1: Segment | F1: City | G1: Country | H1: JoinDate | I1: Email
A2: C0017 | B2: Sophia Rahman | C2: =_xlfn.TEXTBEFORE(Customers[[#This Row],[CustomerName]]," ") -> Sophia | D2: =_xlfn.TEXTAFTER(Customers[[#This Row],[CustomerName]]," ") -> Rahman | E2: SMB | F2: Delhi | G2: India | H2: 44697 | I2: sophia.rahman@example.com
A3: C0133 | B3: Shakib Davis | C3: =_xlfn.TEXTBEFORE(Customers[[#This Row],[CustomerName]]," ") -> Shakib | D3: =_xlfn.TEXTAFTER(Customers[[#This Row],[CustomerName]]," ") -> Davis | E3: consumer | F3: Kolkata | G3: India | H3: 43683 | I3: shakib.davis@example.com
A4: C0315 | B4: Nadia Uddin | C4: =_xlfn.TEXTBEFORE(Customers[[#This Row],[CustomerName]]," ") -> Nadia | D4: =_xlfn.TEXTAFTER(Customers[[#This Row],[CustomerName]]," ") -> Uddin | E4: SMB | F4: Delhi | G4: India | H4: 44051 | I4: nadia.uddin@example.com
A5: C0014 | B5: Ruma Begum | C5: =_xlfn.TEXTBEFORE(Customers[[#This Row],[CustomerName]]," ") -> Ruma | D5: =_xlfn.TEXTAFTER(Customers[[#This Row],[CustomerName]]," ") -> Begum | E5: Home Office | F5: Mumbai | G5: India | H5: 45292 | I5: ruma.begum@example.com
A6: C0167 | B6: Farhan Anderson | C6: =_xlfn.TEXTBEFORE(Customers[[#This Row],[CustomerName]]," ") -> Farhan | D6: =_xlfn.TEXTAFTER(Customers[[#This Row],[CustomerName]]," ") -> Anderson | E6: Consumer | F6: Dhaka | G6: Bangladesh | H6: 44236 | I6: farhan.anderson@example.com
A7: C0472 | B7: Olivia Khan | C7: =_xlfn.TEXTBEFORE(Customers[[#This Row],[CustomerName]]," ") -> Olivia | D7: =_xlfn.TEXTAFTER(Customers[[#This Row],[CustomerName]]," ") -> Khan | E7: Corporate | F7: Mumbai | G7: India | H7: 45396 | I7: olivia.khan@example.com
A8: C0340 | B8: Farhan Smith | C8: =_xlfn.TEXTBEFORE(Customers[[#This Row],[CustomerName]]," ") -> Farhan | D8: =_xlfn.TEXTAFTER(Customers[[#This Row],[CustomerName]]," ") -> Smith | E8: Corporate | F8: Dhaka | G8: Bangladesh | H8: 45752 | I8: farhan.smith@example.com
A9: C0483 | B9: Ayesha Johnson | C9: =_xlfn.TEXTBEFORE(Customers[[#This Row],[CustomerName]]," ") -> Ayesha | D9: =_xlfn.TEXTAFTER(Customers[[#This Row],[CustomerName]]," ") -> Johnson | E9: consumer | F9: Singapore | G9: Singapore | H9: 44067 | I9: ayesha.johnson@example.com
A10: C0058 | B10: Shakib Taylor | C10: =_xlfn.TEXTBEFORE(Customers[[#This Row],[CustomerName]]," ") -> Shakib | D10: =_xlfn.TEXTAFTER(Customers[[#This Row],[CustomerName]]," ") -> Taylor | E10: Home Office | F10: Chittagong | G10: Bangladesh | H10: 43836 | I10: shakib.taylor@example.com
A11: C0028 | B11: Sara Taylor | C11: =_xlfn.TEXTBEFORE(Customers[[#This Row],[CustomerName]]," ") -> Sara | D11: =_xlfn.TEXTAFTER(Customers[[#This Row],[CustomerName]]," ") -> Taylor | E11: SMB | F11: Toronto | G11: Canada | H11: 45440 | I11: sara.taylor@example.com
A12: C0440 | B12: Mim Taylor | C12: =_xlfn.TEXTBEFORE(Customers[[#This Row],[CustomerName]]," ") -> Mim | D12: =_xlfn.TEXTAFTER(Customers[[#This Row],[CustomerName]]," ") -> Taylor | E12: SMB | F12: Rajshahi | G12: Bangladesh | H12: 44420 | I12: mim.taylor@example.com
A13: C0383 | B13: Mitu Moore | C13: =_xlfn.TEXTBEFORE(Customers[[#This Row],[CustomerName]]," ") -> Mitu | D13: =_xlfn.TEXTAFTER(Customers[[#This Row],[CustomerName]]," ") -> Moore | E13: Consumer | F13: Rangpur | G13: Bangladesh | H13: 45740 | I13: mitu.moore@example.com
... A419: C0257 | B419: Ayesha Islam | C419: =_xlfn.TEXTBEFORE(Customers[[#This Row],[CustomerName]]," ") -> Ayesha | D419: =_xlfn.TEXTAFTER(Customers[[#This Row],[CustomerName]]," ") -> Islam | E419: Corporate | F419: Rajshahi | G419: Bangladesh | H419: 45092 | I419: ayesha.islam@example.com

Sheet Orders
A1: OrderID | B1: CustomerID | C1: ProductID | D1: ProductName | E1: Category | F1: SalesRepID | G1: Segment | H1: OrderDate | I1: ShipDate | J1: Quantity | K1: UnitPrice | L1: Discount | M1: Region | N1: Status | O1: PaymentMethod | P1: Order Value | Q1: High Value Order | R1: Priority Region | S1: Order Summary
A2: O04155 | B2: C0009 | C2: P034 | D2: =VLOOKUP(C2,Products[],2,FALSE) -> Labels Deluxe 800 | E2: =VLOOKUP(Orders[[#This Row],[ProductID]],Products[],3,FALSE) -> Office Supplies | F2: R13 | G2: =_xlfn.XLOOKUP(Orders[[#This Row],[CustomerID]],'Customers'!A:A,'Customers'!E:E) -> Corporate | H2: 45468 | I2: 45469 | J2: 4 | K2: 4949.07 | L2: 0.1 | M2: Dhaka | N2: Completed | O2: Mobile Banking | P2: =Orders[[#This Row],[Quantity]]*Orders[[#This Row],[UnitPrice]]*(1-Orders[[#This Row],[Discount]]) -> 17816.652 | Q2: =IF(AND(Orders[[#This Row],[Order Value]]>50000,Orders[[#This Row],[Status]]="Completed"),"Yes","No") -> No | R2: =IF(OR(Orders[[#This Row],[Region]]="Dhaka",Orders[[#This Row],[Region]]="Chattogram"),"Priority","Standard") -> Priority | S2: =_xlfn.CONCAT(Orders[[#This Row],[OrderID]],Orders[[#This Row],[CustomerID]],Orders[[#This Row],[Order Value]]) -> O04155C000917816.652
A3: O05801 | B3: C0435 | C3: P040 | D3: =VLOOKUP(C3,Products[],2,FALSE) -> Women Eco 225 | E3: =VLOOKUP(Orders[[#This Row],[ProductID]],Products[],3,FALSE) -> Apparel | F3: R05 | G3: =_xlfn.XLOOKUP(Orders[[#This Row],[CustomerID]],'Customers'!A:A,'Customers'!E:E) -> Home Office | H3: 45900 | I3: 45914 | J3: 14 | K3: 5008.09 | L3: 0 | M3: Khulna | N3: Cancelled | O3: Card | P3: =Orders[[#This Row],[Quantity]]*Orders[[#This Row],[UnitPrice]]*(1-Orders[[#This Row],[Discount]]) -> 70113.26 | Q3: =IF(AND(Orders[[#This Row],[Order Value]]>50000,Orders[[#This Row],[Status]]="Completed"),"Yes","No") -> No | R3: =IF(OR(Orders[[#This Row],[Region]]="Dhaka",Orders[[#This Row],[Region]]="Chattogram"),"Priority","Standard") -> Standard | S3: =_xlfn.CONCAT(Orders[[#This Row],[OrderID]],Orders[[#This Row],[CustomerID]],Orders[[#This Row],[Order Value]]) -> O05801C043570113.26 | W3: {=_xlfn.UNIQUE(Orders[Region])} -> Dhaka | X3: =SUMIFS(P:P,M:M,W3,N:N,"Completed") -> 14022080
A4: O02507 | B4: C0367 | C4: P028 | D4: =VLOOKUP(C4,Products[],2,FALSE) -> Binders Max 146 | E4: =VLOOKUP(Orders[[#This Row],[ProductID]],Products[],3,FALSE) -> Office Supplies | F4: R06 | G4: =_xlfn.XLOOKUP(Orders[[#This Row],[CustomerID]],'Customers'!A:A,'Customers'!E:E) -> Consumer | H4: 45367 | I4: 45376 | J4: 4 | K4: 3129.25 | L4: 0 | M4: Dhaka | N4: Completed | O4: Bank Transfer | P4: =Orders[[#This Row],[Quantity]]*Orders[[#This Row],[UnitPrice]]*(1-Orders[[#This Row],[Discount]]) -> 12517 | Q4: =IF(AND(Orders[[#This Row],[Order Value]]>50000,Orders[[#This Row],[Status]]="Completed"),"Yes","No") -> No | R4: =IF(OR(Orders[[#This Row],[Region]]="Dhaka",Orders[[#This Row],[Region]]="Chattogram"),"Priority","Standard") -> Priority | S4: =_xlfn.CONCAT(Orders[[#This Row],[OrderID]],Orders[[#This Row],[CustomerID]],Orders[[#This Row],[Order Value]]) -> O02507C036712517 | W4: Khulna | X4: =SUMIFS(P:P,M:M,W4,N:N,"Completed") -> 17547289
A5: O01483 | B5: C0309 | C5: P037 | D5: =VLOOKUP(C5,Products[],2,FALSE) -> #N/A | E5: =VLOOKUP(Orders[[#This Row],[ProductID]],Products[],3,FALSE) -> #N/A | F5: R15 | G5: =_xlfn.XLOOKUP(Orders[[#This Row],[CustomerID]],'Customers'!A:A,'Customers'!E:E) -> SMB | H5: 45789 | I5: 45801 | J5: 13 | K5: 7530.83 | L5: 0.1 | M5: Khulna | N5: Completed | O5: Card | P5: =Orders[[#This Row],[Quantity]]*Orders[[#This Row],[UnitPrice]]*(1-Orders[[#This Row],[Discount]]) -> 88110.711 | Q5: =IF(AND(Orders[[#This Row],[Order Value]]>50000,Orders[[#This Row],[Status]]="Completed"),"Yes","No") -> Yes | R5: =IF(OR(Orders[[#This Row],[Region]]="Dhaka",Orders[[#This Row],[Region]]="Chattogram"),"Priority","Standard") -> Standard | S5: =_xlfn.CONCAT(Orders[[#This Row],[OrderID]],Orders[[#This Row],[CustomerID]],Orders[[#This Row],[Order Value]]) -> O01483C030988110.711 | W5: Rajshahi | X5: =SUMIFS(P:P,M:M,W5,N:N,"Completed") -> 16185613
A6: O00967 | B6: C0315 | C6: P016 | D6: =VLOOKUP(C6,Products[],2,FALSE) -> Tables Max 631 | E6: =VLOOKUP(Orders[[#This Row],[ProductID]],Products[],3,FALSE) -> Furniture | F6: R02 | G6: =_xlfn.XLOOKUP(Orders[[#This Row],[CustomerID]],'Customers'!A:A,'Customers'!E:E) -> SMB | H6: 45491 | I6: 45498 | J6: 5 | K6: 726.6 | L6: 0 | M6: Rajshahi | N6: Completed | O6: Cash | P6: =Orders[[#This Row],[Quantity]]*Orders[[#This Row],[UnitPrice]]*(1-Orders[[#This Row],[Discount]]) -> 3633 | Q6: =IF(AND(Orders[[#This Row],[Order Value]]>50000,Orders[[#This Row],[Status]]="Completed"),"Yes","No") -> No | R6: =IF(OR(Orders[[#This Row],[Region]]="Dhaka",Orders[[#This Row],[Region]]="Chattogram"),"Priority","Standard") -> Standard | S6: =_xlfn.CONCAT(Orders[[#This Row],[OrderID]],Orders[[#This Row],[CustomerID]],Orders[[#This Row],[Order Value]]) -> O00967C03153633 | W6: Chattogram | X6: =SUMIFS(P:P,M:M,W6,N:N,"Completed") -> 18102460
A7: O05171 | B7: C0476 | C7: P045 | D7: =VLOOKUP(C7,Products[],2,FALSE) -> Kids Pro 311 | E7: =VLOOKUP(Orders[[#This Row],[ProductID]],Products[],3,FALSE) -> Apparel | F7: R09 | G7: =_xlfn.XLOOKUP(Orders[[#This Row],[CustomerID]],'Customers'!A:A,'Customers'!E:E) -> Consumer | H7: 45403 | I7: 45403 | J7: 22 | K7: 114.61 | L7: 0.05 | M7: Chattogram | N7: Returned | O7: Cash | P7: =Orders[[#This Row],[Quantity]]*Orders[[#This Row],[UnitPrice]]*(1-Orders[[#This Row],[Discount]]) -> 2395.349 | Q7: =IF(AND(Orders[[#This Row],[Order Value]]>50000,Orders[[#This Row],[Status]]="Completed"),"Yes","No") -> No | R7: =IF(OR(Orders[[#This Row],[Region]]="Dhaka",Orders[[#This Row],[Region]]="Chattogram"),"Priority","Standard") -> Priority | S7: =_xlfn.CONCAT(Orders[[#This Row],[OrderID]],Orders[[#This Row],[CustomerID]],Orders[[#This Row],[Order Value]]) -> O05171C04762395.349 | W7: Sylhet | X7: =SUMIFS(P:P,M:M,W7,N:N,"Completed") -> 16213699
A8: O04755 | B8: C0443 | C8: P053 | D8: =VLOOKUP(C8,Products[],2,FALSE) -> Beverages Standard 258 | E8: =VLOOKUP(Orders[[#This Row],[ProductID]],Products[],3,FALSE) -> Groceries | F8: R04 | G8: =_xlfn.XLOOKUP(Orders[[#This Row],[CustomerID]],'Customers'!A:A,'Customers'!E:E) -> Home Office | H8: 45644 | I8: 45646 | J8: 2 | K8: 6631.61 | L8: 0.2 | M8: Dhaka | N8: Completed | O8: Cash | P8: =Orders[[#This Row],[Quantity]]*Orders[[#This Row],[UnitPrice]]*(1-Orders[[#This Row],[Discount]]) -> 10610.576 | Q8: =IF(AND(Orders[[#This Row],[Order Value]]>50000,Orders[[#This Row],[Status]]="Completed"),"Yes","No") -> No | R8: =IF(OR(Orders[[#This Row],[Region]]="Dhaka",Orders[[#This Row],[Region]]="Chattogram"),"Priority","Standard") -> Priority | S8: =_xlfn.CONCAT(Orders[[#This Row],[OrderID]],Orders[[#This Row],[CustomerID]],Orders[[#This Row],[Order Value]]) -> O04755C044310610.576
A9: O03328 | B9: C0380 | C9: P001 | D9: =VLOOKUP(C9,Products[],2,FALSE) -> Mobile Accessories Lite 346 | E9: =VLOOKUP(Orders[[#This Row],[ProductID]],Products[],3,FALSE) -> Electronics | F9: R08 | G9: =_xlfn.XLOOKUP(Orders[[#This Row],[CustomerID]],'Customers'!A:A,'Customers'!E:E) -> SMB | H9: 45306 | I9: 45313 | J9: 3 | K9: 2031.56 | L9: 0 | M9: Khulna | N9: Completed | O9: Card | P9: =Orders[[#This Row],[Quantity]]*Orders[[#This Row],[UnitPrice]]*(1-Orders[[#This Row],[Discount]]) -> 6094.68 | Q9: =IF(AND(Orders[[#This Row],[Order Value]]>50000,Orders[[#This Row],[Status]]="Completed"),"Yes","No") -> No | R9: =IF(OR(Orders[[#This Row],[Region]]="Dhaka",Orders[[#This Row],[Region]]="Chattogram"),"Priority","Standard") -> Standard | S9: =_xlfn.CONCAT(Orders[[#This Row],[OrderID]],Orders[[#This Row],[CustomerID]],Orders[[#This Row],[Order Value]]) -> O03328C03806094.68
A10: O01457 | B10: C0138 | C10: P018 | D10: =VLOOKUP(C10,Products[],2,FALSE) -> Tables Prime 385 | E10: =VLOOKUP(Orders[[#This Row],[ProductID]],Products[],3,FALSE) -> Furniture | F10: R06 | G10: =_xlfn.XLOOKUP(Orders[[#This Row],[CustomerID]],'Customers'!A:A,'Customers'!E:E) -> Consumer | H10: 45464 | I10: 45477 | J10: 22 | K10: 5992.96 | L10: 0.15 | M10: Rajshahi | N10: Returned | O10: Card | P10: =Orders[[#This Row],[Quantity]]*Orders[[#This Row],[UnitPrice]]*(1-Orders[[#This Row],[Discount]]) -> 112068.35 | Q10: =IF(AND(Orders[[#This Row],[Order Value]]>50000,Orders[[#This Row],[Status]]="Completed"),"Yes","No") -> No | R10: =IF(OR(Orders[[#This Row],[Region]]="Dhaka",Orders[[#This Row],[Region]]="Chattogram"),"Priority","Standard") -> Standard | S10: =_xlfn.CONCAT(Orders[[#This Row],[OrderID]],Orders[[#This Row],[CustomerID]],Orders[[#This Row],[Order Value]]) -> O01457C0138112068.352
A11: O05981 | B11: C0314 | C11: P009 | D11: =VLOOKUP(C11,Products[],2,FALSE) -> Cameras Classic 922 | E11: =VLOOKUP(Orders[[#This Row],[ProductID]],Products[],3,FALSE) -> Electronics | F11: R08 | G11: =_xlfn.XLOOKUP(Orders[[#This Row],[CustomerID]],'Customers'!A:A,'Customers'!E:E) -> consumer | H11: 45591 | I11: 45589 | J11: 24 | K11: 1021.86 | L11: 0 | M11: Dhaka | N11: Completed | O11: Cash | P11: =Orders[[#This Row],[Quantity]]*Orders[[#This Row],[UnitPrice]]*(1-Orders[[#This Row],[Discount]]) -> 24524.64 | Q11: =IF(AND(Orders[[#This Row],[Order Value]]>50000,Orders[[#This Row],[Status]]="Completed"),"Yes","No") -> No | R11: =IF(OR(Orders[[#This Row],[Region]]="Dhaka",Orders[[#This Row],[Region]]="Chattogram"),"Priority","Standard") -> Priority | S11: =_xlfn.CONCAT(Orders[[#This Row],[OrderID]],Orders[[#This Row],[CustomerID]],Orders[[#This Row],[Order Value]]) -> O05981C031424524.64
A12: O05155 | B12: C0112 | C12: P003 | D12: =VLOOKUP(C12,Products[],2,FALSE) -> Mobile Accessories Mini 994 | E12: =VLOOKUP(Orders[[#This Row],[ProductID]],Products[],3,FALSE) -> Electronics | F12: R13 | G12: =_xlfn.XLOOKUP(Orders[[#This Row],[CustomerID]],'Customers'!A:A,'Customers'!E:E) -> consumer | H12: 45461 | I12: 45467 | J12: 23 | K12: 889.39 | L12: 0.1 | M12: Sylhet | N12: Completed | O12: Bank Transfer | P12: =Orders[[#This Row],[Quantity]]*Orders[[#This Row],[UnitPrice]]*(1-Orders[[#This Row],[Discount]]) -> 18410.373 | Q12: =IF(AND(Orders[[#This Row],[Order Value]]>50000,Orders[[#This Row],[Status]]="Completed"),"Yes","No") -> No | R12: =IF(OR(Orders[[#This Row],[Region]]="Dhaka",Orders[[#This Row],[Region]]="Chattogram"),"Priority","Standard") -> Standard | S12: =_xlfn.CONCAT(Orders[[#This Row],[OrderID]],Orders[[#This Row],[CustomerID]],Orders[[#This Row],[Order Value]]) -> O05155C011218410.373 | W12: {=_xlfn.UNIQUE(F2:F246)} -> R13 | X12: =COUNTIFS(F:F,W12,N:N,"Completed") -> 143
A13: O03536 | B13: C0462 | C13: P019 | D13: =VLOOKUP(C13,Products[],2,FALSE) -> Storage Plus 812 | E13: =VLOOKUP(Orders[[#This Row],[ProductID]],Products[],3,FALSE) -> Furniture | F13: R05 | G13: =_xlfn.XLOOKUP(Orders[[#This Row],[CustomerID]],'Customers'!A:A,'Customers'!E:E) -> Consumer | H13: 45410 | I13: 45423 | J13: 5 | K13: 423.87 | L13: 0.15 | M13: Chattogram | N13: Completed | O13: Cash | P13: =Orders[[#This Row],[Quantity]]*Orders[[#This Row],[UnitPrice]]*(1-Orders[[#This Row],[Discount]]) -> 1801.4475 | Q13: =IF(AND(Orders[[#This Row],[Order Value]]>50000,Orders[[#This Row],[Status]]="Completed"),"Yes","No") -> No | R13: =IF(OR(Orders[[#This Row],[Region]]="Dhaka",Orders[[#This Row],[Region]]="Chattogram"),"Priority","Standard") -> Priority | S13: =_xlfn.CONCAT(Orders[[#This Row],[OrderID]],Orders[[#This Row],[CustomerID]],Orders[[#This Row],[Order Value]]) -> O03536C04621801.4475 | W13: R05 | X13: =COUNTIFS(F:F,W13,N:N,"Completed") -> 118
A14: O00668 | B14: C0290 | C14: P009 | D14: =VLOOKUP(C14,Products[],2,FALSE) -> Cameras Classic 922 | E14: =VLOOKUP(Orders[[#This Row],[ProductID]],Products[],3,FALSE) -> Electronics | F14: R14 | G14: =_xlfn.XLOOKUP(Orders[[#This Row],[CustomerID]],'Customers'!A:A,'Customers'!E:E) -> Home Office | H14: 45584 | I14: 45584 | J14: 14 | K14: 508.82 | L14: 0.15 | M14: Dhaka | N14: Completed | O14: Bank Transfer | P14: =Orders[[#This Row],[Quantity]]*Orders[[#This Row],[UnitPrice]]*(1-Orders[[#This Row],[Discount]]) -> 6054.958 | Q14: =IF(AND(Orders[[#This Row],[Order Value]]>50000,Orders[[#This Row],[Status]]="Completed"),"Yes","No") -> No | R14: =IF(OR(Orders[[#This Row],[Region]]="Dhaka",Orders[[#This Row],[Region]]="Chattogram"),"Priority","Standard") -> Priority | S14: =_xlfn.CONCAT(Orders[[#This Row],[OrderID]],Orders[[#This Row],[CustomerID]],Orders[[#This Row],[Order Value]]) -> O00668C02906054.958 | W14: R06 | X14: =COUNTIFS(F:F,W14,N:N,"Completed") -> 90
A15: O05939 | B15: C0265 | C15: P052 | D15: =VLOOKUP(C15,Products[],2,FALSE) -> Beverages Plus 578 | E15: =VLOOKUP(Orders[[#This Row],[ProductID]],Products[],3,FALSE) -> Groceries | F15: R06 | G15: =_xlfn.XLOOKUP(Orders[[#This Row],[CustomerID]],'Customers'!A:A,'Customers'!E:E) -> consumer | H15: 45816 | I15: 45827 | J15: 2 | K15: 2772.46 | L15: 0 | M15: Rajshahi | N15: Pending | O15: Card | P15: =Orders[[#This Row],[Quantity]]*Orders[[#This Row],[UnitPrice]]*(1-Orders[[#This Row],[Discount]]) -> 5544.92 | Q15: =IF(AND(Orders[[#This Row],[Order Value]]>50000,Orders[[#This Row],[Status]]="Completed"),"Yes","No") -> No | R15: =IF(OR(Orders[[#This Row],[Region]]="Dhaka",Orders[[#This Row],[Region]]="Chattogram"),"Priority","Standard") -> Standard | S15: =_xlfn.CONCAT(Orders[[#This Row],[OrderID]],Orders[[#This Row],[CustomerID]],Orders[[#This Row],[Order Value]]) -> O05939C02655544.92 | W15: R15 | X15: =COUNTIFS(F:F,W15,N:N,"Completed") -> 123
A16: O05208 | B16: C0500 | C16: P013 | D16: =VLOOKUP(C16,Products[],2,FALSE) -> Chairs Mini 737 | E16: =VLOOKUP(Orders[[#This Row],[ProductID]],Products[],3,FALSE) -> Furniture | F16: R11 | G16: =_xlfn.XLOOKUP(Orders[[#This Row],[CustomerID]],'Customers'!A:A,'Customers'!E:E) -> Home Office | H16: 45397 | I16: 45410 | J16: 10 | K16: 969.89 | L16: 0 | M16: Rajshahi | N16: Completed | O16: Cash | P16: =Orders[[#This Row],[Quantity]]*Orders[[#This Row],[UnitPrice]]*(1-Orders[[#This Row],[Discount]]) -> 9698.9 | Q16: =IF(AND(Orders[[#This Row],[Order Value]]>50000,Orders[[#This Row],[Status]]="Completed"),"Yes","No") -> No | R16: =IF(OR(Orders[[#This Row],[Region]]="Dhaka",Orders[[#This Row],[Region]]="Chattogram"),"Priority","Standard") -> Standard | S16: =_xlfn.CONCAT(Orders[[#This Row],[OrderID]],Orders[[#This Row],[CustomerID]],Orders[[#This Row],[Order Value]]) -> O05208C05009698.9 | W16: R02 | X16: =COUNTIFS(F:F,W16,N:N,"Completed") -> 125
A17: O04412 | B17: C0158 | C17: P006 | D17: =VLOOKUP(C17,Products[],2,FALSE) -> Laptops Lite 159 | E17: =VLOOKUP(Orders[[#This Row],[ProductID]],Products[],3,FALSE) -> Electronics | F17: R02 | G17: =_xlfn.XLOOKUP(Orders[[#This Row],[CustomerID]],'Customers'!A:A,'Customers'!E:E) -> Home Office | H17: 45448 | I17: 45446 | J17: 1 | K17: 2158.85 | L17: 0 | M17: Dhaka | N17: Cancelled | O17: Cash | P17: =Orders[[#This Row],[Quantity]]*Orders[[#This Row],[UnitPrice]]*(1-Orders[[#This Row],[Discount]]) -> 2158.85 | Q17: =IF(AND(Orders[[#This Row],[Order Value]]>50000,Orders[[#This Row],[Status]]="Completed"),"Yes","No") -> No | R17: =IF(OR(Orders[[#This Row],[Region]]="Dhaka",Orders[[#This Row],[Region]]="Chattogram"),"Priority","Standard") -> Priority | S17: =_xlfn.CONCAT(Orders[[#This Row],[OrderID]],Orders[[#This Row],[CustomerID]],Orders[[#This Row],[Order Value]]) -> O04412C01582158.85 | W17: R09 | X17: =COUNTIFS(F:F,W17,N:N,"Completed") -> 92
A18: O03850 | B18: C0108 | C18: P038 | D18: =VLOOKUP(C18,Products[],2,FALSE) -> Men Max 446 | E18: =VLOOKUP(Orders[[#This Row],[ProductID]],Products[],3,FALSE) -> Apparel | F18: R14 | G18: =_xlfn.XLOOKUP(Orders[[#This Row],[CustomerID]],'Customers'!A:A,'Customers'!E:E) -> Home Office | H18: 45566 | I18: 45574 | J18: 10 | K18: 3507.95 | L18: 0 | M18: Chattogram | N18: Completed | O18: Mobile Banking | P18: =Orders[[#This Row],[Quantity]]*Orders[[#This Row],[UnitPrice]]*(1-Orders[[#This Row],[Discount]]) -> 35079.5 | Q18: =IF(AND(Orders[[#This Row],[Order Value]]>50000,Orders[[#This Row],[Status]]="Completed"),"Yes","No") -> No | R18: =IF(OR(Orders[[#This Row],[Region]]="Dhaka",Orders[[#This Row],[Region]]="Chattogram"),"Priority","Standard") -> Priority | S18: =_xlfn.CONCAT(Orders[[#This Row],[OrderID]],Orders[[#This Row],[CustomerID]],Orders[[#This Row],[Order Value]]) -> O03850C010835079.5 | W18: R04 | X18: =COUNTIFS(F:F,W18,N:N,"Completed") -> 94
A19: O01563 | B19: C0356 | C19: P047 | D19: =VLOOKUP(C19,Products[],2,FALSE) -> Footwear Eco 867 | E19: =VLOOKUP(Orders[[#This Row],[ProductID]],Products[],3,FALSE) -> Apparel | F19: R06 | G19: =_xlfn.XLOOKUP(Orders[[#This Row],[CustomerID]],'Customers'!A:A,'Customers'!E:E) -> consumer | H19: 45379 | I19: 45386 | J19: 20 | K19: 2270.02 | L19: 0 | M19: Sylhet | N19: Completed | O19: Card | P19: =Orders[[#This Row],[Quantity]]*Orders[[#This Row],[UnitPrice]]*(1-Orders[[#This Row],[Discount]]) -> 45400.4 | Q19: =IF(AND(Orders[[#This Row],[Order Value]]>50000,Orders[[#This Row],[Status]]="Completed"),"Yes","No") -> No | R19: =IF(OR(Orders[[#This Row],[Region]]="Dhaka",Orders[[#This Row],[Region]]="Chattogram"),"Priority","Standard") -> Standard | S19: =_xlfn.CONCAT(Orders[[#This Row],[OrderID]],Orders[[#This Row],[CustomerID]],Orders[[#This Row],[Order Value]]) -> O01563C035645400.4 | W19: R08 | X19: =COUNTIFS(F:F,W19,N:N,"Completed") -> 113
A20: O04193 | B20: C0397 | C20: P049 | D20: =VLOOKUP(C20,Products[],2,FALSE) -> Snacks Standard 963 | E20: =VLOOKUP(Orders[[#This Row],[ProductID]],Products[],3,FALSE) -> Groceries | F20: R07 | G20: =_xlfn.XLOOKUP(Orders[[#This Row],[CustomerID]],'Customers'!A:A,'Customers'!E:E) -> Home Office | H20: 45781 | I20: 45792 | J20: 12 | K20: 1279.93 | L20: 0 | M20: Dhaka | N20: Cancelled | O20: Mobile Banking | P20: =Orders[[#This Row],[Quantity]]*Orders[[#This Row],[UnitPrice]]*(1-Orders[[#This Row],[Discount]]) -> 15359.16 | Q20: =IF(AND(Orders[[#This Row],[Order Value]]>50000,Orders[[#This Row],[Status]]="Completed"),"Yes","No") -> No | R20: =IF(OR(Orders[[#This Row],[Region]]="Dhaka",Orders[[#This Row],[Region]]="Chattogram"),"Priority","Standard") -> Priority | S20: =_xlfn.CONCAT(Orders[[#This Row],[OrderID]],Orders[[#This Row],[CustomerID]],Orders[[#This Row],[Order Value]]) -> O04193C039715359.16 | W20: R14 | X20: =COUNTIFS(F:F,W20,N:N,"Completed") -> 93
A21: O04500 | B21: C0408 | C21: P012 | D21: =VLOOKUP(C21,Products[],2,FALSE) -> Audio Prime 238 | E21: =VLOOKUP(Orders[[#This Row],[ProductID]],Products[],3,FALSE) -> Electronics | F21: R15 | G21: =_xlfn.XLOOKUP(Orders[[#This Row],[CustomerID]],'Customers'!A:A,'Customers'!E:E) -> Home Office | H21: 45763 | I21: 45766 | J21: 2 | K21: 5217.02 | L21: 0.1 | M21: Rajshahi | N21: Completed | O21: Cash | P21: =Orders[[#This Row],[Quantity]]*Orders[[#This Row],[UnitPrice]]*(1-Orders[[#This Row],[Discount]]) -> 9390.636 | Q21: =IF(AND(Orders[[#This Row],[Order Value]]>50000,Orders[[#This Row],[Status]]="Completed"),"Yes","No") -> No | R21: =IF(OR(Orders[[#This Row],[Region]]="Dhaka",Orders[[#This Row],[Region]]="Chattogram"),"Priority","Standard") -> Standard | S21: =_xlfn.CONCAT(Orders[[#This Row],[OrderID]],Orders[[#This Row],[CustomerID]],Orders[[#This Row],[Order Value]]) -> O04500C04089390.636 | W21: R11 | X21: =COUNTIFS(F:F,W21,N:N,"Completed") -> 109
A22: O00579 | B22: C0349 | C22: P047 | D22: =VLOOKUP(C22,Products[],2,FALSE) -> Footwear Eco 867 | E22: =VLOOKUP(Orders[[#This Row],[ProductID]],Products[],3,FALSE) -> Apparel | F22: R15 | G22: =_xlfn.XLOOKUP(Orders[[#This Row],[CustomerID]],'Customers'!A:A,'Customers'!E:E) -> Consumer | H22: 45555 | I22: 45554 | J22: 21 | K22: 4618.41 | L22: 0 | M22: Sylhet | N22: Completed | O22: Cash | P22: =Orders[[#This Row],[Quantity]]*Orders[[#This Row],[UnitPrice]]*(1-Orders[[#This Row],[Discount]]) -> 96986.61 | Q22: =IF(AND(Orders[[#This Row],[Order Value]]>50000,Orders[[#This Row],[Status]]="Completed"),"Yes","No") -> Yes | R22: =IF(OR(Orders[[#This Row],[Region]]="Dhaka",Orders[[#This Row],[Region]]="Chattogram"),"Priority","Standard") -> Standard | S22: =_xlfn.CONCAT(Orders[[#This Row],[OrderID]],Orders[[#This Row],[CustomerID]],Orders[[#This Row],[Order Value]]) -> O00579C034996986.61 | W22: R07 | X22: =COUNTIFS(F:F,W22,N:N,"Completed") -> 115
A23: O04931 | B23: C0469 | C23: P020 | D23: =VLOOKUP(C23,Products[],2,FALSE) -> Storage Max 865 | E23: =VLOOKUP(Orders[[#This Row],[ProductID]],Products[],3,FALSE) -> Furniture | F23: R11 | G23: =_xlfn.XLOOKUP(Orders[[#This Row],[CustomerID]],'Customers'!A:A,'Customers'!E:E) -> Consumer | H23: 45897 | I23: 45907 | J23: 21 | K23: 843 | L23: 0.2 | M23: Khulna | N23: Pending | O23: Cash | P23: =Orders[[#This Row],[Quantity]]*Orders[[#This Row],[UnitPrice]]*(1-Orders[[#This Row],[Discount]]) -> 14162.4 | Q23: =IF(AND(Orders[[#This Row],[Order Value]]>50000,Orders[[#This Row],[Status]]="Completed"),"Yes","No") -> No | R23: =IF(OR(Orders[[#This Row],[Region]]="Dhaka",Orders[[#This Row],[Region]]="Chattogram"),"Priority","Standard") -> Standard | S23: =_xlfn.CONCAT(Orders[[#This Row],[OrderID]],Orders[[#This Row],[CustomerID]],Orders[[#This Row],[Order Value]]) -> O04931C046914162.4 | W23: R12 | X23: =COUNTIFS(F:F,W23,N:N,"Completed") -> 111
A24: O04487 | B24: C0392 | C24: P024 | D24: =VLOOKUP(C24,Products[],2,FALSE) -> Decor Lite 474 | E24: =VLOOKUP(Orders[[#This Row],[ProductID]],Products[],3,FALSE) -> Furniture | F24: R12 | G24: =_xlfn.XLOOKUP(Orders[[#This Row],[CustomerID]],'Customers'!A:A,'Customers'!E:E) -> Home Office | H24: 45429 | I24: 45441 | J24: 4 | K24: 3577.92 | L24: 0.05 | M24: Chattogram | N24: Completed | O24: Bank Transfer | P24: =Orders[[#This Row],[Quantity]]*Orders[[#This Row],[UnitPrice]]*(1-Orders[[#This Row],[Discount]]) -> 13596.096 | Q24: =IF(AND(Orders[[#This Row],[Order Value]]>50000,Orders[[#This Row],[Status]]="Completed"),"Yes","No") -> No | R24: =IF(OR(Orders[[#This Row],[Region]]="Dhaka",Orders[[#This Row],[Region]]="Chattogram"),"Priority","Standard") -> Priority | S24: =_xlfn.CONCAT(Orders[[#This Row],[OrderID]],Orders[[#This Row],[CustomerID]],Orders[[#This Row],[Order Value]]) -> O04487C039213596.096 | W24: R01 | X24: =COUNTIFS(F:F,W24,N:N,"Completed") -> 110
... A26: O04009 | B26: C0265 | C26: P027 | D26: =VLOOKUP(C26,Products[],2,FALSE) -> Paper Prime 195 | E26: =VLOOKUP(Orders[[#This Row],[ProductID]],Products[],3,FALSE) -> Office Supplies | F26: R12 | G26: =_xlfn.XLOOKUP(Orders[[#This Row],[CustomerID]],'Customers'!A:A,'Customers'!E:E) -> consumer | H26: 45644 | I26: 45643 | J26: 1 | K26: 1962.79 | L26: 0.15 | M26: Chattogram | N26: Completed | O26: Cash | P26: =Orders[[#This Row],[Quantity]]*Orders[[#This Row],[UnitPrice]]*(1-Orders[[#This Row],[Discount]]) -> 1668.3715 | Q26: =IF(AND(Orders[[#This Row],[Order Value]]>50000,Orders[[#This Row],[Status]]="Completed"),"Yes","No") -> No | R26: =IF(OR(Orders[[#This Row],[Region]]="Dhaka",Orders[[#This Row],[Region]]="Chattogram"),"Priority","Standard") -> Priority | S26: =_xlfn.CONCAT(Orders[[#This Row],[OrderID]],Orders[[#This Row],[CustomerID]],Orders[[#This Row],[Order Value]]) -> O04009C02651668.3715 | W26: R03 | X26: =COUNTIFS(F:F,W26,N:N,"Completed") -> 103
A27: O04712 | B27: C0233 | C27: P017 | D27: =VLOOKUP(C27,Products[],2,FALSE) -> Tables Plus 844 | E27: =VLOOKUP(Orders[[#This Row],[ProductID]],Products[],3,FALSE) -> Furniture | F27: R15 | G27: =_xlfn.XLOOKUP(Orders[[#This Row],[CustomerID]],'Customers'!A:A,'Customers'!E:E) -> Home Office | H27: 45554 | I27: 45562 | J27: 24 | K27: 7630.24 | L27: 0.15 | M27: Rajshahi | N27: Completed | O27: Bank Transfer | P27: =Orders[[#This Row],[Quantity]]*Orders[[#This Row],[UnitPrice]]*(1-Orders[[#This Row],[Discount]]) -> 155656.9 | Q27: =IF(AND(Orders[[#This Row],[Order Value]]>50000,Orders[[#This Row],[Status]]="Completed"),"Yes","No") -> Yes | R27: =IF(OR(Orders[[#This Row],[Region]]="Dhaka",Orders[[#This Row],[Region]]="Chattogram"),"Priority","Standard") -> Standard | S27: =_xlfn.CONCAT(Orders[[#This Row],[OrderID]],Orders[[#This Row],[CustomerID]],Orders[[#This Row],[Order Value]]) -> O04712C0233155656.896
A28: O04853 | B28: C0212 | C28: P009 | D28: =VLOOKUP(C28,Products[],2,FALSE) -> Cameras Classic 922 | E28: =VLOOKUP(Orders[[#This Row],[ProductID]],Products[],3,FALSE) -> Electronics | F28: R15 | G28: =_xlfn.XLOOKUP(Orders[[#This Row],[CustomerID]],'Customers'!A:A,'Customers'!E:E) -> SMB | H28: 45463 | I28: 45468 | J28: 4 | K28: 535.9 | L28: 0.05 | M28: Khulna | N28: Pending | O28: Cash | P28: =Orders[[#This Row],[Quantity]]*Orders[[#This Row],[UnitPrice]]*(1-Orders[[#This Row],[Discount]]) -> 2036.42 | Q28: =IF(AND(Orders[[#This Row],[Order Value]]>50000,Orders[[#This Row],[Status]]="Completed"),"Yes","No") -> No | R28: =IF(OR(Orders[[#This Row],[Region]]="Dhaka",Orders[[#This Row],[Region]]="Chattogram"),"Priority","Standard") -> Standard | S28: =_xlfn.CONCAT(Orders[[#This Row],[OrderID]],Orders[[#This Row],[CustomerID]],Orders[[#This Row],[Order Value]]) -> O04853C02122036.42
A29: O04798 | B29: C0100 | C29: P053 | D29: =VLOOKUP(C29,Products[],2,FALSE) -> Beverages Standard 258 | E29: =VLOOKUP(Orders[[#This Row],[ProductID]],Products[],3,FALSE) -> Groceries | F29: R14 | G29: =_xlfn.XLOOKUP(Orders[[#This Row],[CustomerID]],'Customers'!A:A,'Customers'!E:E) -> Corporate | H29: 45594 | I29: 45603 | J29: 16 | K29: 3917.56 | L29: 0.05 | M29: Khulna | N29: Cancelled | O29: Bank Transfer | P29: =Orders[[#This Row],[Quantity]]*Orders[[#This Row],[UnitPrice]]*(1-Orders[[#This Row],[Discount]]) -> 59546.912 | Q29: =IF(AND(Orders[[#This Row],[Order Value]]>50000,Orders[[#This Row],[Status]]="Completed"),"Yes","No") -> No | R29: =IF(OR(Orders[[#This Row],[Region]]="Dhaka",Orders[[#This Row],[Region]]="Chattogram"),"Priority","Standard") -> Standard | S29: =_xlfn.CONCAT(Orders[[#This Row],[OrderID]],Orders[[#This Row],[CustomerID]],Orders[[#This Row],[Order Value]]) -> O04798C010059546.912 | W29: {=_xlfn.UNIQUE(G:G)} -> Segment
A30: O03444 | B30: C0403 | C30: P046 | D30: =VLOOKUP(C30,Products[],2,FALSE) -> Footwear Deluxe 366 | E30: =VLOOKUP(Orders[[#This Row],[ProductID]],Products[],3,FALSE) -> Apparel | F30: R09 | G30: =_xlfn.XLOOKUP(Orders[[#This Row],[CustomerID]],'Customers'!A:A,'Customers'!E:E) -> Consumer | H30: 45495 | I30: 45505 | J30: 1 | K30: 1438.76 | L30: 0.05 | M30: Dhaka | N30: Pending | O30: Bank Transfer | P30: =Orders[[#This Row],[Quantity]]*Orders[[#This Row],[UnitPrice]]*(1-Orders[[#This Row],[Discount]]) -> 1366.822 | Q30: =IF(AND(Orders[[#This Row],[Order Value]]>50000,Orders[[#This Row],[Status]]="Completed"),"Yes","No") -> No | R30: =IF(OR(Orders[[#This Row],[Region]]="Dhaka",Orders[[#This Row],[Region]]="Chattogram"),"Priority","Standard") -> Priority | S30: =_xlfn.CONCAT(Orders[[#This Row],[OrderID]],Orders[[#This Row],[CustomerID]],Orders[[#This Row],[Order Value]]) -> O03444C04031366.822 | W30: Corporate | X30: =AVERAGEIFS(P:P,G:G,W30) -> 46323.282
A31: O00570 | B31: C0415 | C31: P033 | D31: =VLOOKUP(C31,Products[],2,FALSE) -> Pens Deluxe 654 | E31: =VLOOKUP(Orders[[#This Row],[ProductID]],Products[],3,FALSE) -> Office Supplies | F31: R13 | G31: =_xlfn.XLOOKUP(Orders[[#This Row],[CustomerID]],'Customers'!A:A,'Customers'!E:E) -> Corporate | H31: 45325 | I31: 45324 | J31: 14 | K31: 7447.83 | L31: 0 | M31: Chattogram | N31: Completed | O31: Cash | P31: =Orders[[#This Row],[Quantity]]*Orders[[#This Row],[UnitPrice]]*(1-Orders[[#This Row],[Discount]]) -> 104269.62 | Q31: =IF(AND(Orders[[#This Row],[Order Value]]>50000,Orders[[#This Row],[Status]]="Completed"),"Yes","No") -> Yes | R31: =IF(OR(Orders[[#This Row],[Region]]="Dhaka",Orders[[#This Row],[Region]]="Chattogram"),"Priority","Standard") -> Priority | S31: =_xlfn.CONCAT(Orders[[#This Row],[OrderID]],Orders[[#This Row],[CustomerID]],Orders[[#This Row],[Order Value]]) -> O00570C0415104269.62 | W31: Home Office | X31: =AVERAGEIFS(P:P,G:G,W31) -> 50768.401
A32: O02576 | B32: C0293 | C32: P033 | D32: =VLOOKUP(C32,Products[],2,FALSE) -> Pens Deluxe 654 | E32: =VLOOKUP(Orders[[#This Row],[ProductID]],Products[],3,FALSE) -> Office Supplies | F32: R13 | G32: =_xlfn.XLOOKUP(Orders[[#This Row],[CustomerID]],'Customers'!A:A,'Customers'!E:E) -> Corporate | H32: 45437 | I32: 45447 | J32: 5 | K32: 6014.84 | L32: 0 | M32: Rajshahi | N32: Completed | O32: Mobile Banking | P32: =Orders[[#This Row],[Quantity]]*Orders[[#This Row],[UnitPrice]]*(1-Orders[[#This Row],[Discount]]) -> 30074.2 | Q32: =IF(AND(Orders[[#This Row],[Order Value]]>50000,Orders[[#This Row],[Status]]="Completed"),"Yes","No") -> No | R32: =IF(OR(Orders[[#This Row],[Region]]="Dhaka",Orders[[#This Row],[Region]]="Chattogram"),"Priority","Standard") -> Standard | S32: =_xlfn.CONCAT(Orders[[#This Row],[OrderID]],Orders[[#This Row],[CustomerID]],Orders[[#This Row],[Order Value]]) -> O02576C029330074.2 | W32: Consumer | X32: =AVERAGEIFS(P:P,G:G,W32) -> 47904.317
A33: O03473 | B33: C0155 | C33: P010 | D33: =VLOOKUP(C33,Products[],2,FALSE) -> Audio Classic 927 | E33: =VLOOKUP(Orders[[#This Row],[ProductID]],Products[],3,FALSE) -> Electronics | F33: R13 | G33: =_xlfn.XLOOKUP(Orders[[#This Row],[CustomerID]],'Customers'!A:A,'Customers'!E:E) -> Consumer | H33: 45975 | I33: 45984 | J33: 10 | K33: 4723.63 | L33: 0.15 | M33: Dhaka | N33: Completed | O33: Cash | P33: =Orders[[#This Row],[Quantity]]*Orders[[#This Row],[UnitPrice]]*(1-Orders[[#This Row],[Discount]]) -> 40150.855 | Q33: =IF(AND(Orders[[#This Row],[Order Value]]>50000,Orders[[#This Row],[Status]]="Completed"),"Yes","No") -> No | R33: =IF(OR(Orders[[#This Row],[Region]]="Dhaka",Orders[[#This Row],[Region]]="Chattogram"),"Priority","Standard") -> Priority | S33: =_xlfn.CONCAT(Orders[[#This Row],[OrderID]],Orders[[#This Row],[CustomerID]],Orders[[#This Row],[Order Value]]) -> O03473C015540150.855 | W33: SMB | X33: =AVERAGEIFS(P:P,G:G,W33) -> 50144.913
A34: O03292 | B34: C0391 | C34: P026 | D34: =VLOOKUP(C34,Products[],2,FALSE) -> Paper Lite 570 | E34: =VLOOKUP(Orders[[#This Row],[ProductID]],Products[],3,FALSE) -> Office Supplies | F34: R01 | G34: =_xlfn.XLOOKUP(Orders[[#This Row],[CustomerID]],'Customers'!A:A,'Customers'!E:E) -> Consumer | H34: 45308 | I34: 45310 | J34: 21 | K34: 3452.38 | L34: 0 | M34: Khulna | N34: Returned | O34: Bank Transfer | P34: =Orders[[#This Row],[Quantity]]*Orders[[#This Row],[UnitPrice]]*(1-Orders[[#This Row],[Discount]]) -> 72499.98 | Q34: =IF(AND(Orders[[#This Row],[Order Value]]>50000,Orders[[#This Row],[Status]]="Completed"),"Yes","No") -> No | R34: =IF(OR(Orders[[#This Row],[Region]]="Dhaka",Orders[[#This Row],[Region]]="Chattogram"),"Priority","Standard") -> Standard | S34: =_xlfn.CONCAT(Orders[[#This Row],[OrderID]],Orders[[#This Row],[CustomerID]],Orders[[#This Row],[Order Value]]) -> O03292C039172499.98 | W34: 0
A35: O03720 | B35: C0183 | C35: P050 | D35: =VLOOKUP(C35,Products[],2,FALSE) -> Snacks Deluxe 862 | E35: =VLOOKUP(Orders[[#This Row],[ProductID]],Products[],3,FALSE) -> Groceries | F35: R01 | G35: =_xlfn.XLOOKUP(Orders[[#This Row],[CustomerID]],'Customers'!A:A,'Customers'!E:E) -> Home Office | H35: 45976 | I35: 45985 | J35: 16 | K35: 1712.24 | L35: 0.05 | M35: Dhaka | N35: Completed | O35: Card | P35: =Orders[[#This Row],[Quantity]]*Orders[[#This Row],[UnitPrice]]*(1-Orders[[#This Row],[Discount]]) -> 26026.048 | Q35: =IF(AND(Orders[[#This Row],[Order Value]]>50000,Orders[[#This Row],[Status]]="Completed"),"Yes","No") -> No | R35: =IF(OR(Orders[[#This Row],[Region]]="Dhaka",Orders[[#This Row],[Region]]="Chattogram"),"Priority","Standard") -> Priority | S35: =_xlfn.CONCAT(Orders[[#This Row],[OrderID]],Orders[[#This Row],[CustomerID]],Orders[[#This Row],[Order Value]]) -> O03720C018326026.048
A36: O00239 | B36: C0155 | C36: P044 | D36: =VLOOKUP(C36,Products[],2,FALSE) -> Kids Pro 394 | E36: =VLOOKUP(Orders[[#This Row],[ProductID]],Products[],3,FALSE) -> Apparel | F36: R09 | G36: =_xlfn.XLOOKUP(Orders[[#This Row],[CustomerID]],'Customers'!A:A,'Customers'!E:E) -> Consumer | H36: 46004 | I36: 46010 | J36: 10 | K36: 5514.88 | L36: 0.05 | M36: Khulna | N36: Completed | O36: Cash | P36: =Orders[[#This Row],[Quantity]]*Orders[[#This Row],[UnitPrice]]*(1-Orders[[#This Row],[Discount]]) -> 52391.36 | Q36: =IF(AND(Orders[[#This Row],[Order Value]]>50000,Orders[[#This Row],[Status]]="Completed"),"Yes","No") -> Yes | R36: =IF(OR(Orders[[#This Row],[Region]]="Dhaka",Orders[[#This Row],[Region]]="Chattogram"),"Priority","Standard") -> Standard | S36: =_xlfn.CONCAT(Orders[[#This Row],[OrderID]],Orders[[#This Row],[CustomerID]],Orders[[#This Row],[Order Value]]) -> O00239C015552391.36
A37: O02889 | B37: C0306 | C37: P032 | D37: =VLOOKUP(C37,Products[],2,FALSE) -> Pens Mini 821 | E37: =VLOOKUP(Orders[[#This Row],[ProductID]],Products[],3,FALSE) -> Office Supplies | F37: R14 | G37: =_xlfn.XLOOKUP(Orders[[#This Row],[CustomerID]],'Customers'!A:A,'Customers'!E:E) -> consumer | H37: 45339 | I37: 45345 | J37: 7 | K37: 3328.59 | L37: 0 | M37: Rajshahi | N37: Pending | O37: Mobile Banking | P37: =Orders[[#This Row],[Quantity]]*Orders[[#This Row],[UnitPrice]]*(1-Orders[[#This Row],[Discount]]) -> 23300.13 | Q37: =IF(AND(Orders[[#This Row],[Order Value]]>50000,Orders[[#This Row],[Status]]="Completed"),"Yes","No") -> No | R37: =IF(OR(Orders[[#This Row],[Region]]="Dhaka",Orders[[#This Row],[Region]]="Chattogram"),"Priority","Standard") -> Standard | S37: =_xlfn.CONCAT(Orders[[#This Row],[OrderID]],Orders[[#This Row],[CustomerID]],Orders[[#This Row],[Order Value]]) -> O02889C030623300.13 | W37: =SUMIF(C:C,C2,J:J) -> 732
A38: O01424 | B38: C0354 | C38: P010 | D38: =VLOOKUP(C38,Products[],2,FALSE) -> Audio Classic 927 | E38: =VLOOKUP(Orders[[#This Row],[ProductID]],Products[],3,FALSE) -> Electronics | F38: R09 | G38: =_xlfn.XLOOKUP(Orders[[#This Row],[CustomerID]],'Customers'!A:A,'Customers'!E:E) -> consumer | H38: 45765 | I38: 45779 | J38: 2 | K38: 2788.87 | L38: 0 | M38: Sylhet | N38: Completed | O38: Card | P38: =Orders[[#This Row],[Quantity]]*Orders[[#This Row],[UnitPrice]]*(1-Orders[[#This Row],[Discount]]) -> 5577.74 | Q38: =IF(AND(Orders[[#This Row],[Order Value]]>50000,Orders[[#This Row],[Status]]="Completed"),"Yes","No") -> No | R38: =IF(OR(Orders[[#This Row],[Region]]="Dhaka",Orders[[#This Row],[Region]]="Chattogram"),"Priority","Standard") -> Standard | S38: =_xlfn.CONCAT(Orders[[#This Row],[OrderID]],Orders[[#This Row],[CustomerID]],Orders[[#This Row],[Order Value]]) -> O01424C03545577.74
A39: O05786 | B39: C0336 | C39: P027 | D39: =VLOOKUP(C39,Products[],2,FALSE) -> Paper Prime 195 | E39: =VLOOKUP(Orders[[#This Row],[ProductID]],Products[],3,FALSE) -> Office Supplies | F39: R15 | G39: =_xlfn.XLOOKUP(Orders[[#This Row],[CustomerID]],'Customers'!A:A,'Customers'!E:E) -> SMB | H39: 45693 | I39: 45705 | J39: 22 | K39: 3447.47 | L39: 0.05 | M39: Rajshahi | N39: Cancelled | O39: Cash | P39: =Orders[[#This Row],[Quantity]]*Orders[[#This Row],[UnitPrice]]*(1-Orders[[#This Row],[Discount]]) -> 72052.123 | Q39: =IF(AND(Orders[[#This Row],[Order Value]]>50000,Orders[[#This Row],[Status]]="Completed"),"Yes","No") -> No | R39: =IF(OR(Orders[[#This Row],[Region]]="Dhaka",Orders[[#This Row],[Region]]="Chattogram"),"Priority","Standard") -> Standard | S39: =_xlfn.CONCAT(Orders[[#This Row],[OrderID]],Orders[[#This Row],[CustomerID]],Orders[[#This Row],[Order Value]]) -> O05786C033672052.123
A40: O03293 | B40: C0445 | C40: P003 | D40: =VLOOKUP(C40,Products[],2,FALSE) -> Mobile Accessories Mini 994 | E40: =VLOOKUP(Orders[[#This Row],[ProductID]],Products[],3,FALSE) -> Electronics | F40: R10 | G40: =_xlfn.XLOOKUP(Orders[[#This Row],[CustomerID]],'Customers'!A:A,'Customers'!E:E) -> SMB | H40: 45367 | I40: 45373 | J40: 6 | K40: 6344.56 | L40: 0 | M40: Khulna | N40: Pending | O40: Cash | P40: =Orders[[#This Row],[Quantity]]*Orders[[#This Row],[UnitPrice]]*(1-Orders[[#This Row],[Discount]]) -> 38067.36 | Q40: =IF(AND(Orders[[#This Row],[Order Value]]>50000,Orders[[#This Row],[Status]]="Completed"),"Yes","No") -> No | R40: =IF(OR(Orders[[#This Row],[Region]]="Dhaka",Orders[[#This Row],[Region]]="Chattogram"),"Priority","Standard") -> Standard | S40: =_xlfn.CONCAT(Orders[[#This Row],[OrderID]],Orders[[#This Row],[CustomerID]],Orders[[#This Row],[Order Value]]) -> O03293C044538067.36
A41: O02149 | B41: C0052 | C41: P009 | D41: =VLOOKUP(C41,Products[],2,FALSE) -> Cameras Classic 922 | E41: =VLOOKUP(Orders[[#This Row],[ProductID]],Products[],3,FALSE) -> Electronics | F41: R07 | G41: =_xlfn.XLOOKUP(Orders[[#This Row],[CustomerID]],'Customers'!A:A,'Customers'!E:E) -> Corporate | H41: 45754 | I41: 45761 | J41: 5 | K41: 1075.7 | L41: 0 | M41: Chattogram | N41: Cancelled | O41: Mobile Banking | P41: =Orders[[#This Row],[Quantity]]*Orders[[#This Row],[UnitPrice]]*(1-Orders[[#This Row],[Discount]]) -> 5378.5 | Q41: =IF(AND(Orders[[#This Row],[Order Value]]>50000,Orders[[#This Row],[Status]]="Completed"),"Yes","No") -> No | R41: =IF(OR(Orders[[#This Row],[Region]]="Dhaka",Orders[[#This Row],[Region]]="Chattogram"),"Priority","Standard") -> Priority | S41: =_xlfn.CONCAT(Orders[[#This Row],[OrderID]],Orders[[#This Row],[CustomerID]],Orders[[#This Row],[Order Value]]) -> O02149C00525378.5
...

Sheet SalesReps
A1: SalesRepID | B1: SalesRepName | C1: Region | D1: MonthlyTarget
A2: R01 | B2: Tanvir Johnson | C2: Rajshahi | D2: 301637
A3: R02 | B3: Ruma Rahman | C3: Sylhet | D3: 680530
A4: R03 | B4: Mim Miller | C4: Dhaka | D4: 444030
A5: R04 | B5: Arif Miller | C5: Chattogram | D5: 556209
A6: R05 | B6: Tanvir Rahman | C6: Dhaka | D6: 467111
A7: R06 | B7: Sadia Brown | C7: Rajshahi | D7: 669574
A8: R07 | B8: Tania Alam | C8: Chattogram | D8: 797995
A9: R08 | B9: Daniel Smith | C9: Rajshahi | D9: 677068
A10: R09 | B10: Sara Smith | C10: Chattogram | D10: 758822
A11: R10 | B11: David Hossain | C11: Khulna | D11: 767616
A12: R11 | B12: Sabbir Miller | C12: Khulna | D12: 254063
A13: R12 | B13: James Begum | C13: Khulna | D13: 352030
... A16: R15 | B16: Shakib Anderson | C16: Sylhet | D16: 230087

Sheet Sheet2
B3: Sum of Order Value | G3: Status
B4: Region | C4: OrderDate (Year) | D4: OrderDate (Quarter) | E4: OrderDate (Month) | F4: OrderDate | G4: Cancelled | H4: Completed | I4: Pending | J4: Returned
B5: Chattogram | C5: 2024 | G5: 4324789.1 | H5: 9870198.8 | I5: 3569691.1 | J5: 3773737.9
C6: 2025 | G6: 3708361.7 | H6: 10166896 | I6: 3572229 | J6: 3697552.2
B7: Chattogram Total | G7: 8033150.8 | H7: 20037094 | I7: 7141920.1 | J7: 7471290.1
B8: Dhaka | C8: 2024 | G8: 1860602.3 | H8: 4539179 | I8: 2282836.8 | J8: 1330592.2
C9: 2025 | G9: 1502288.5 | H9: 5894141.2 | I9: 1599613.3 | J9: 2263673.5
B10: Dhaka Total | G10: 3362890.8 | H10: 10433320 | I10: 3882450.2 | J10: 3594265.7
B11: Khulna | C11: 2024 | G11: 4041044.7 | H11: 11151484 | I11: 4036324.6 | J11: 4121183
C12: 2025 | G12: 3943419.7 | H12: 11878453 | I12: 4199327.1 | J12: 3747389.8
B13: Khulna Total | G13: 7984464.4 | H13: 23029937 | I13: 8235651.7 | J13: 7868572.7
B14: Rajshahi | C14: 2024 | G14: 2415164.6 | H14: 8500899.7 | I14: 2214064.9 | J14: 2468831.9
C15: 2025 | G15: 2987148.4 | H15: 7800841.8 | I15: 2136097.4 | J15: 2973167.9
B16: Rajshahi Total | G16: 5402313 | H16: 16301741 | I16: 4350162.3 | J16: 5441999.8
B17: Sylhet | C17: 2024 | G17: 2336446.5 | H17: 6184566.1 | I17: 2503669.3 | J17: 1773964.1
C18: 2025 | G18: 1603228.7 | H18: 6084482.3 | I18: 1976303.1 | J18: 1405066.3
B19: Sylhet Total | G19: 3939675.2 | H19: 12269048 | I19: 4479972.4 | J19: 3179030.3
